Workbook

Sheet Sheet1
A1: Checknumber | B1: ChunkID | C1: Speaker | D1: Label | E1: Count | F1: Start time | G1: End time | H1: WAV_Link | I1: Valid | J1: Reason | K1: Close to | L1: Glued | M1: Other DF | N1: Multi-FP | O1: FP-length | P1: Struct. cont. | Q1: Dis. type | R1: Anneliese, HELP! | S1: ManualCorrectionOrtho | T1: Word2Word | U1: Phrase | V1: PCOMP | W1: vorn_valid4exp | X1: vorn_mit | Y1: vorn_ohne | Z1: hinten_valid4exp | AA1: hinten_mit | AB1: hinten_ohne | AC1: ganz_valid4exp | AD1: ganz_ohne | AE1: ganz_mit
A2: 4 | C2: 001M | D2: äh | E2: 004 | F2: 488.143 | G2: 497.586 | H2: file:///C:/TI_projekt_daten/Audio/001M_äh_004.wav | I2: no | J2: not a FP | S2: äh = die? | U2: ja ich meine es ist schon ein bisschen hügelig aber viele Berge also richtige Berge die sind auch äh sind weiter weg als da in Graz [ die ] hm
A3: 9 | C3: 001M | D3: äh | E3: 009 | F3: 2618.002 | G3: 2629.517 | H3: file:///C:/TI_projekt_daten/Audio/001M_äh_009.wav | I3: no | J3: short FP | U3: das ist übrigens ich glaube das <*ENG>C (+ $N + $N +) hat so eine Liste auf seiner <*ENG>Homepage <breathingIN> da ist so bei den äh bei den , #fünfzehn interessantesten Gebäuden der [ Welt oben oder ] Architekturen ja
A4: 17 | C4: 001M | D4: ahm | E4: 008 | F4: 3584.796 | G4: 3593.238 | H4: file:///C:/TI_projekt_daten/Audio/001M_ahm_008.wav | I4: no | J4: other df | L4: no | M4: no | N4: no | O4: mid | P4: no | Q4: 2 | T4: vor ein paar Jahren waren ahm haben wir (+ in + in +) Oberösterreich | U4: [ genau apropos Sonnenflecken ] <breathingIN> irgendwann auf ein <&b>p vor ein paar Jahren waren ahm haben wir (+ in + in +) Oberösterreich haben wir Nord=Lichter gesehen [ das war ziemlich <*ENG>cool ]
A5: 10 | C5: 001M | D5: ahm | E5: 001 | F5: 297.108 | G5: 305.594 | H5: file:///C:/TI_projekt_daten/Audio/001M_ahm_001.wav | I5: no | J5: answer | U5: <smack> <breathingIN> <noise> [ boah <breathingOUT> ] <breathingIN> <noise> ahm ja grundsätzlich schon <breathingIN> aber ein bisschen mehr Hügel hätte ich gerne es ist mir zu flach | V5: <breathingIN><smack><breathingIN> <noise> change <breathingOUT> <breathingIN> <noise> hes hold hold <breathingIN> hold hold
A6: 3 | B6: 001M_462.1_Typ1 | C6: 001M | D6: äh | E6: 003 | F6: 460.452 | G6: 469.638 | H6: file:///C:/TI_projekt_daten/Audio/001M_äh_003.wav | I6: yes | L6: back | M6: no | N6: no | O6: mid | P6: yes | Q6: 1 | T6: es wäre dort eine interessante äh Firma gewesen | U6: naja sagen wir so also nach Innsbruck wollte ich nicht aber die es wäre dort eine interessante äh Firma gewesen also sagen wir { <breathingIN> } [ ja eigentlich ] | W6: 1 | X6: super | Y6: super | Z6: 1 | AB6: super
A7: 1 | C7: 001M | D7: äh | E7: 001 | F7: 363.385 | G7: 371.768 | H7: file:///C:/TI_projekt_daten/Audio/001M_äh_001.wav | I7: no | J7: not enough speech | U7: [ <laughter> ] [ <laughter> ] <breathingIN> [ äh ] <noise> <smack>nein [ <noise> ja ] schon [ oder ] so
A8: 2 | C8: 001M | D8: äh | E8: 002 | F8: 396.672 | G8: 405.012 | H8: file:///C:/TI_projekt_daten/Audio/001M_äh_002.wav | I8: no | J8: not enough speech | U8: <breathingIN> naja <&L>Wochenendhaus { <noise> } [ <laughter> ] { <breathingIN> } äh [ achso ] [ mhm ]
A9: 5 | C9: 001M | D9: äh | E9: 005 | F9: 585.763 | G9: 595.46 | H9: file:///C:/TI_projekt_daten/Audio/001M_äh_005.wav | I9: no | J9: answer | U9: die öffentlichen Verkehrsmittel <&L>deswegen <&L>fahre <&L>ich <&L>immer <&L>mit <&L>dem <&L>Rad { <breathingIN> } äh ja weil alles #drei mal so lange dauert
A10: 12 | C10: 001M | D10: ahm | E10: 003 | F10: 825.475 | G10: 834.044 | H10: file:///C:/TI_projekt_daten/Audio/001M_ahm_003.wav | I10: no | L10: no | M10: yes | N10: no | O10: long | P10: maybe | T10: und dann ahm naja habe ich halt erfahren | U10: aufgescheuchten <*DIAL>Hendeln <breathingIN> [ <laughter> ] <breathingIN> und dann ahm naja habe ich halt erfahren dass er <breathingIN> dass er <#noise> eben die Klausur ist { <breathingIN> }
A11: 6 | C11: 001M | D11: äh | E11: 006 | F11: 889.11 | G11: 897.408 | H11: file:///C:/TI_projekt_daten/Audio/001M_äh_006.wav | I11: no | J11: not enough speech | U11: [ mhm ] [ <laughter> ] { <breathingIN> } [ äh ] [ naja ]
A12: 7 | C12: 001M | D12: äh | E12: 007 | F12: 1030.259 | G12: 1038.558 | H12: file:///C:/TI_projekt_daten/Audio/001M_äh_007.wav | I12: no | J12: not enough speech | U12: [ <laughter> ] <breathingIN> [ äh ] { <breathingIN> } [ mhm ] { <noise> } [ ja keine Ahnung also ]
A13: 8 | C13: 001M | D13: äh | E13: 008 | F13: 1463.072 | G13: 1471.334 | H13: file:///C:/TI_projekt_daten/Audio/001M_äh_008.wav | I13: no | J13: double talk | U13: Hundeüberrest <&L>dann <&L>herumliegen ist [ <&L>dann <&L>auch <&L>schon <&L>Wurst ] { <breathingIN> } [ äh ] { <noise> } ah stimmt [ ja ] mhm
A14: 13 | C14: 001M | D14: ahm | E14: 004 | F14: 1539.479 | G14: 1547.84 | H14: file:///C:/TI_projekt_daten/Audio/001M_ahm_004.wav | I14: no | J14: other df | U14: du <*DIAL>deppert mhm [ ja aber weil_du ] das sagst { <noise> } [ ahm ] { <breathingIN> } <noise> [ <noise> unsere ] Kinder haben irgendwie in letzter Zeit so Vorlieben also interessieren sich halt für Weltraum und Sterne
A15: 14 | C15: 001M | D15: ahm | E15: 005 | F15: 1553.385 | G15: 1562.532 | H15: file:///C:/TI_projekt_daten/Audio/001M_ahm_005.wav | I15: no | J15: long pause | K15: 15 | L15: no | M15: yes | N15: no | O15: long | T15: und dann hab ich gelesen dass ahm die ah ich glaube jedes Jahr zwanzigtausend ahm Steine aus dem Weltraum auf die Erde fallen | U15: und halt auch Meteoriten <breathingIN> (+ und + und +) so und dann habe ich gelesen dass ahm <noise> die <#noise> ah ich glaube <noise>
A16: 16 | C16: 001M | D16: ahm | E16: 007 | F16: 1646.078 | G16: 1655.324 | H16: file:///C:/TI_projekt_daten/Audio/001M_ahm_007.wav | I16: no | J16: double talk | U16: [ mhm ] [ mhm ] [ ja ahm das stimmt ja ] [ mhm ] { <breathingIN> } { <noise> } [ genau ] [ mhm ]
A17: 18 | C17: 002M | D17: äh | E17: 001 | F17: 234.184 | G17: 243.37 | H17: file:///C:/TI_projekt_daten/Audio/002M_äh_001.wav | I17: no | J17: double talk | U17: { <breathingIN> } [ mhm ] <breathingOUT> <noise> Münzgrabenstraße ist auch nicht so schön <breathingOUT> { <breathingIN> } [ äh Hötzendorfstraße ] [ <smack> <breathingIN> ] [ ja das stimmt ] <breathingOUT> { <noise> } { <#noise> } { <breathingIN> } | V17: <noise> <smack> <breathingIN> hrt <breathingOUT> <noise> change_hold <breathingOUT> <breathingIN> hes change <breathingIN><smack><breathingIN> part_hold@ change <breathingOUT> <noise> <breathingIN> hrt
A18: 38 | C18: 002M | D18: ähm | E18: 001 | F18: 264.679 | G18: 273.822 | H18: file:///C:/TI_projekt_daten/Audio/002M_ähm_001.wav | I18: no | J18: not enough speech | U18: [ was ein Kanal ? ] { <breathingOUT> } [ ja Kanal ] ja stimmt geh <&b>we oh schön <breathingIN> ähm Gewässer { <breathingOUT> } <breathingIN> [ da haben wir ] auch nur (+ sehr + sehr +) [ wenige ] in [ Graz ] { <breathingIN> } | V18: hold_question hold_question <breathingOUT> hold hold part_hold@ hold part_hold@ disruption@ hold hold <breathingIN> hes hold <breathingOUT> <breathingIN> cont change <breathingIN> part
A19: 23 | C19: 002M | D19: äh | E19: 006 | F19: 1517.608 | G19: 1525.969 | H19: file:///C:/TI_projekt_daten/Audio/002M_äh_006.wav | I19: no | J19: long pause | U19: ein ziemlich großer Stein <breathingOUT> <breathingIN> so groß zirka wie <breathingIN> äh <breathingOUT> puh jetzt muss ich einmal überlegen
A20: 28 | C20: 002M | D20: äh | E20: 011 | F20: 2067.444 | G20: 2076.109 | H20: file:///C:/TI_projekt_daten/Audio/002M_äh_011.wav | I20: no | J20: name | U20: <noise> naja { <breathingIN> } uh ja Hader ist gut ja <breathingIN> äh <breathingIN> ich habe gesehen die <*ENG>science <*ENG>busters [ im Orpheum ]
A21: 29 | C21: 002M | D21: äh | E21: 012 | F21: 2223.244 | G21: 2231.868 | H21: file:///C:/TI_projekt_daten/Audio/002M_äh_012.wav | I21: no | J21: need more | K21: 30 | U21: nein kein Sauerteig { <breathingIN> } (+ äh + äh +) normales Roggenbrot ja halt so [ äh ] <&b>Trockeng genau
A22: 30 | C22: 002M | D22: äh | E22: 013 | F22: 2226.667 | G22: 2235.201 | H22: file:///C:/TI_projekt_daten/Audio/002M_äh_013.wav | I22: no | J22: other df | K22: 29 | U22: { <breathingIN> } (+ äh + äh +) normales Roggenbrot ja halt so [ äh ] <&b>Trockeng genau Trockengerm [ Trockenhefe ] oh ja das es geht schon
A23: 41 | C23: 002M | D23: ähm | E23: 004 | F23: 2266.697 | G23: 2275.025 | H23: file:///C:/TI_projekt_daten/Audio/002M_ähm_004.wav | I23: no | J23: rare word | U23: [ im Englischen ] heißt es <*ENG>the <*ENG>sour <*ENG>dough [ finde ich sehr nett ] { <breathingIN> } [ ja egal ] <breathingIN> [ ähm ] da haben wir einen Hermannkuchen gemacht [ kennst_du einen Hermannkuchen ] <breathingIN> da wurde der Sauerteig vor zig Jahren einmal
A24: 32 | C24: 002M | D24: äh | E24: 015 | F24: 2760.3 | G24: 2768.768 | H24: file:///C:/TI_projekt_daten/Audio/002M_äh_015.wav | I24: no | J24: short after | U24: die haben ja eh den ein oder anderen Bach der durch Graz geht [ unterirdisch ] [ äh ] fließen lassen der
A25: 35 | C25: 002M | D25: äh | E25: 018 | F25: 3365.113 | G25: 3373.619 | H25: file:///C:/TI_projekt_daten/Audio/002M_äh_018.wav | I25: no | J25: name | U25: was war deine Frage was man da so [ macht in ] Marwiesen auf [ so einem Truppenübungsplatz ] <breathingIN> äh <breathingIN> Gefechte simulieren
A26: 31 | C26: 002M | D26: äh | E26: 014 | F26: 2296.353 | G26: 2304.895 | H26: file:///C:/TI_projekt_daten/Audio/002M_äh_014.wav | I26: no | J26: not a FP | U26: [ verbreitet ja ] <breathingIN> aber ich bin mir sicher dass es die Steirer auch drauf haben [ ich mein ob ] sie es drauf haben [ äh ] { <breathingIN> } [ bin ich mir nicht sicher aber sie werden es vielleicht schon einmal gehört ] haben [ ja ]
A27: 42 | C27: 002M | D27: ähm | E27: 005 | F27: 3375.801 | G27: 3384.921 | H27: file:///C:/TI_projekt_daten/Audio/002M_ähm_005.wav | I27: no | J27: double talk | U27: Gefechte [ du lernst ] bitte [ nein ähm ] nein Knallmunition [ ja ]
A28: 44 | C28: 003M | D28: äh | E28: 001 | F28: 44.61 | G28: 53.15 | H28: file:///C:/TI_projekt_daten/Audio/003M_äh_001.wav | I28: no | J28: disruption at wrong point | L28: no | M28: yes | N28: no | O28: mid | P28: yes | R28: x | T28: und da sehe ich so von der Ferne äh erste Stra okay also erste Straßenbahn fährt weg | U28: bin ich zur Keplerbrücke gegangen <breathingOUT> <smack> <breathingIN> und da sehe ich so von der Ferne <breathingIN> äh <breathingOUT><smack> <smack> <breathingIN> erste <&b>Stra ok Straßenbahn fährt weg denke ich mir ok die nächste kommt dann in #vier oder #fünf Minuten | V28: hold <breathingOUT> <smack> <breathingIN> disruption hold hold hold hold <breathingIN>
A29: 11 | C29: 001M | D29: ahm | E29: 002 | F29: 783.333 | G29: 792.049 | H29: file:///C:/TI_projekt_daten/Audio/001M_ahm_002.wav | I29: yes | J29: pause und aber da weg | L29: no | M29: no | N29: no | O29: long | P29: new | Q29: 4 | T29: das war ganz witzig aber da ahm ja ich weiß nicht | U29: ja <&b>f das war ganz witzig <noise> [ aber ] <noise> da <noise> ahm <breathingOUT> <breathingIN> ja ich weiß nicht das hat irgendwie
A30: 70 | C30: 003M | D30: ähm | E30: 001 | F30: 205.93 | G30: 214.527 | H30: file:///C:/TI_projekt_daten/Audio/003M_ähm_001.wav | I30: no | J30: disruption at wrong point | L30: no | M30: yes | N30: no | O30: long | P30: maybe | T30: der nimmt meine ähm mein direkt mein mein Stimmbandsignal auf | U30: der nimmt meine <noise> <smack> <breathingIN> ähm <breathingOUT> <breathingIN> mein direkt mein <breathingIN> mein Stimmbandsignal auf | V30: disruption change <breathingIN><smack><breathingIN>
A31: 52 | C31: 003M | D31: äh | E31: 009 | F31: 732.736 | G31: 744.659 | H31: file:///C:/TI_projekt_daten/Audio/003M_äh_009.wav | I31: no | J31: rare word | U31: [ nein ] ahm <smack> wie ist das eigentlich bei Narkolepsie ist das <&b>ver verbunden mit äh anderen Beeinträchtigungen [ oder ] <*DIAL>knackst einfach manchmal weg
A32: 55 | C32: 003M | D32: äh | E32: 012 | F32: 905.95 | G32: 914.526 | H32: file:///C:/TI_projekt_daten/Audio/003M_äh_012.wav | I32: no | J32: short after | U32: ich hoffe ich war bin nicht zu ah <smack> wie sagt man äh ja also
A33: 71 | C33: 003M | D33: ähm | E33: 002 | F33: 1992.474 | G33: 2001.596 | H33: file:///C:/TI_projekt_daten/Audio/003M_ähm_002.wav | I33: no | J33: hard to understand | U33: aber jedenfalls der Andreas und ich haben heute auch schon geredet über eine Couch wir brauchen auch unbedingt [ eine Couch im ] jetzt in <&b>uns ähm unserem Büro
A34: 68 | C34: 003M | D34: äh | E34: 025 | F34: 2951.748 | G34: 2962.364 | H34: file:///C:/TI_projekt_daten/Audio/003M_äh_025.wav | I34: no | J34: double talk | U34: [ mhm ] { <smack> } [ aber das ] ist bei dem schon klar gewesen dass das [ äh ] <noise> dass wie das funktioniert #S#
A35: 47 | C35: 003M | D35: äh | E35: 004 | F35: 216.192 | G35: 224.949 | H35: file:///C:/TI_projekt_daten/Audio/003M_äh_004.wav | I35: no | J35: not enough speech | U35: [ <breathingIN> <smack> <breathingIN> ] { <smack> } <smack> äh <#noise> <breathingIN> <#noise> <breathingIN><smack><breathingIN> hm man erkennt die Grundfrequenz (+ von + von +) der Sprache direkter | V35: <breathingIN><smack><breathingIN> <smack> <smack> hes <breathingIN> <breathingIN><smack><breathingIN> hold cont cont
A36: 74 | C36: 003M | D36: ahm | E36: 002 | F36: 288.122 | G36: 296.708 | H36: file:///C:/TI_projekt_daten/Audio/003M_ahm_002.wav | I36: no | J36: initial FP | U36: <breathingOUT> <smack> <noise> { <breathingIN> } { <breathingOUT> } [ <breathingIN><smack><breathingIN> ] ahm <smack> ja der hat da eben Sprache aufgenommen <breathingOUT> [ also ] | V36: <breathingOUT> <smack> <noise> <breathingIN> <breathingOUT> <breathingIN><smack><breathingIN> hes <smack> hold hold <breathingOUT> @disruption <breathingIN>
A37: 51 | C37: 003M | D37: äh | E37: 008 | F37: 684.399 | G37: 693.62 | H37: file:///C:/TI_projekt_daten/Audio/003M_äh_008.wav | I37: no | J37: rare word | U37: <smack> <breathingIN> [ Hypnotherapie ] ist das äh Schlaftherapie
A38: 76 | C38: 003M | D38: ahm | E38: 004 | F38: 731.315 | G38: 740.126 | H38: file:///C:/TI_projekt_daten/Audio/003M_ahm_004.wav | I38: no | J38: initial FP | U38: [ nein ] ahm <smack> wie ist das eigentlich bei Narkolepsie ist das <&b>ver verbunden mit äh
A39: 53 | C39: 003M | D39: äh | E39: 010 | F39: 838.49 | G39: 850.099 | H39: file:///C:/TI_projekt_daten/Audio/003M_äh_010.wav | I39: no | J39: short FP | U39: welcher Zweite <smack> <breathingIN> ah seine äh der seine #drei #viertel Kilo Tortellini [ gegessen hat ] das war der Hannes ja
A40: 54 | C40: 003M | D40: äh | E40: 011 | F40: 869.081 | G40: 878.083 | H40: file:///C:/TI_projekt_daten/Audio/003M_äh_011.wav | I40: no | J40: initial FP | U40: das ist jetzt peinlich [ hm ] äh <smack> wir könnten irgendwie , Gott fragen
...

Sheet Statistics
A1: Categories | B1: 1 | C1: 2 | D1: 3 | E1: 4
B2: =COUNTIFS(Tabelle1[[#All],[Dis. type]], B1, Tabelle1[[#All],[Valid]], "Yes") -> 92 | C2: =COUNTIFS(Tabelle1[[#All],[Dis. type]], C1, Tabelle1[[#All],[Valid]], "Yes") -> 33 | D2: =COUNTIFS(Tabelle1[[#All],[Dis. type]], D1, Tabelle1[[#All],[Valid]], "Yes") -> 2 | E2: =COUNTIFS(Tabelle1[[#All],[Dis. type]], E1, Tabelle1[[#All],[Valid]], "Yes") -> 32
A3: Valid | B3: yes | C3: no | D3: maybe
B4: =COUNTIF(Tabelle1[[#All],[Valid]], Statistics!B3) -> 167 | C4: =COUNTIF(Tabelle1[[#All],[Valid]], Statistics!C3) -> 703 | D4: =COUNTIF(Tabelle1[[#All],[Valid]], Statistics!D3) -> 0
A6: Reasons | B6: {=_xlfn.UNIQUE(Tabelle1[Reason])} -> not a FP | C6: =COUNTIFS(Tabelle1[[#All],[Reason]],Statistics!B6, Tabelle1[[#All],[Valid]], "No") -> 3 | E6: =IF($C6=0, "", B6) -> not a FP | F6: =IF($C6=0, "", C6) -> 3 | H6: {=_xlfn.SORTBY(E6:F101, F6:F101, -1)}
A7: (for no) | B7: short FP | C7: =COUNTIFS(Tabelle1[[#All],[Reason]],Statistics!B7, Tabelle1[[#All],[Valid]], "No") -> 39 | E7: =IF($C7=0, "", B7) -> short FP | F7: =IF($C7=0, "", C7) -> 39
B8: other df | C8: =COUNTIFS(Tabelle1[[#All],[Reason]],Statistics!B8, Tabelle1[[#All],[Valid]], "No") -> 198 | E8: =IF($C8=0, "", B8) -> other df | F8: =IF($C8=0, "", C8) -> 198
B9: answer | C9: =COUNTIFS(Tabelle1[[#All],[Reason]],Statistics!B9, Tabelle1[[#All],[Valid]], "No") -> 12 | E9: =IF($C9=0, "", B9) -> answer | F9: =IF($C9=0, "", C9) -> 12
B10: 0 | C10: =COUNTIFS(Tabelle1[[#All],[Reason]],Statistics!B10, Tabelle1[[#All],[Valid]], "No") -> 0 | E10: =IF($C10=0, "", B10) | F10: =IF($C10=0, "", C10)
B11: not enough speech | C11: =COUNTIFS(Tabelle1[[#All],[Reason]],Statistics!B11, Tabelle1[[#All],[Valid]], "No") -> 27 | E11: =IF($C11=0, "", B11) -> not enough speech | F11: =IF($C11=0, "", C11) -> 27
B12: double talk | C12: =COUNTIFS(Tabelle1[[#All],[Reason]],Statistics!B12, Tabelle1[[#All],[Valid]], "No") -> 74 | E12: =IF($C12=0, "", B12) -> double talk | F12: =IF($C12=0, "", C12) -> 74
B13: long pause | C13: =COUNTIFS(Tabelle1[[#All],[Reason]],Statistics!B13, Tabelle1[[#All],[Valid]], "No") -> 9 | E13: =IF($C13=0, "", B13) -> long pause | F13: =IF($C13=0, "", C13) -> 9
B14: name | C14: =COUNTIFS(Tabelle1[[#All],[Reason]],Statistics!B14, Tabelle1[[#All],[Valid]], "No") -> 25 | E14: =IF($C14=0, "", B14) -> name | F14: =IF($C14=0, "", C14) -> 25
B15: need more | C15: =COUNTIFS(Tabelle1[[#All],[Reason]],Statistics!B15, Tabelle1[[#All],[Valid]], "No") -> 3 | E15: =IF($C15=0, "", B15) -> need more | F15: =IF($C15=0, "", C15) -> 3
B16: rare word | C16: =COUNTIFS(Tabelle1[[#All],[Reason]],Statistics!B16, Tabelle1[[#All],[Valid]], "No") -> 40 | E16: =IF($C16=0, "", B16) -> rare word | F16: =IF($C16=0, "", C16) -> 40
B17: short after | C17: =COUNTIFS(Tabelle1[[#All],[Reason]],Statistics!B17, Tabelle1[[#All],[Valid]], "No") -> 8 | E17: =IF($C17=0, "", B17) -> short after | F17: =IF($C17=0, "", C17) -> 8
B18: disruption at wrong point | C18: =COUNTIFS(Tabelle1[[#All],[Reason]],Statistics!B18, Tabelle1[[#All],[Valid]], "No") -> 4 | E18: =IF($C18=0, "", B18) -> disruption at wrong point | F18: =IF($C18=0, "", C18) -> 4
B19: pause und aber da weg | C19: =COUNTIFS(Tabelle1[[#All],[Reason]],Statistics!B19, Tabelle1[[#All],[Valid]], "No") -> 0 | E19: =IF($C19=0, "", B19) | F19: =IF($C19=0, "", C19)
B20: hard to understand | C20: =COUNTIFS(Tabelle1[[#All],[Reason]],Statistics!B20, Tabelle1[[#All],[Valid]], "No") -> 49 | E20: =IF($C20=0, "", B20) -> hard to understand | F20: =IF($C20=0, "", C20) -> 49
B21: initial FP | C21: =COUNTIFS(Tabelle1[[#All],[Reason]],Statistics!B21, Tabelle1[[#All],[Valid]], "No") -> 50 | E21: =IF($C21=0, "", B21) -> initial FP | F21: =IF($C21=0, "", C21) -> 50
B22: spelling | C22: =COUNTIFS(Tabelle1[[#All],[Reason]],Statistics!B22, Tabelle1[[#All],[Valid]], "No") -> 2 | E22: =IF($C22=0, "", B22) -> spelling | F22: =IF($C22=0, "", C22) -> 2
... B57: cut out "mit"? | C57: =COUNTIFS(Tabelle1[[#All],[Reason]],Statistics!B57, Tabelle1[[#All],[Valid]], "No") -> 0 | E57: =IF($C57=0, "", B57) | F57: =IF($C57=0, "", C57)
C58: =COUNTIFS(Tabelle1[[#All],[Reason]],Statistics!B58, Tabelle1[[#All],[Valid]], "No") -> 0 | E58: =IF($C58=0, "", B58) | F58: =IF($C58=0, "", C58)
C59: =COUNTIFS(Tabelle1[[#All],[Reason]],Statistics!B59, Tabelle1[[#All],[Valid]], "No") -> 0 | E59: =IF($C59=0, "", B59) | F59: =IF($C59=0, "", C59)
C60: =COUNTIFS(Tabelle1[[#All],[Reason]],Statistics!B60, Tabelle1[[#All],[Valid]], "No") -> 0 | E60: =IF($C60=0, "", B60) | F60: =IF($C60=0, "", C60)
C61: =COUNTIFS(Tabelle1[[#All],[Reason]],Statistics!B61, Tabelle1[[#All],[Valid]], "No") -> 0 | E61: =IF($C61=0, "", B61) | F61: =IF($C61=0, "", C61)
C62: =COUNTIFS(Tabelle1[[#All],[Reason]],Statistics!B62, Tabelle1[[#All],[Valid]], "No") -> 0 | E62: =IF($C62=0, "", B62) | F62: =IF($C62=0, "", C62)
C63: =COUNTIFS(Tabelle1[[#All],[Reason]],Statistics!B63, Tabelle1[[#All],[Valid]], "No") -> 0 | E63: =IF($C63=0, "", B63) | F63: =IF($C63=0, "", C63) | H63: other df | I63: 198
C64: =COUNTIFS(Tabelle1[[#All],[Reason]],Statistics!B64, Tabelle1[[#All],[Valid]], "No") -> 0 | E64: =IF($C64=0, "", B64) | F64: =IF($C64=0, "", C64) | H64: double talk | I64: 74
C65: =COUNTIFS(Tabelle1[[#All],[Reason]],Statistics!B65, Tabelle1[[#All],[Valid]], "No") -> 0 | E65: =IF($C65=0, "", B65) | F65: =IF($C65=0, "", C65) | H65: initial FP | I65: 50
C66: =COUNTIFS(Tabelle1[[#All],[Reason]],Statistics!B66, Tabelle1[[#All],[Valid]], "No") -> 0 | E66: =IF($C66=0, "", B66) | F66: =IF($C66=0, "", C66) | H66: hard to understand | I66: 49
C67: =COUNTIFS(Tabelle1[[#All],[Reason]],Statistics!B67, Tabelle1[[#All],[Valid]], "No") -> 0 | E67: =IF($C67=0, "", B67) | F67: =IF($C67=0, "", C67) | H67: rare word | I67: 40
C68: =COUNTIFS(Tabelle1[[#All],[Reason]],Statistics!B68, Tabelle1[[#All],[Valid]], "No") -> 0 | E68: =IF($C68=0, "", B68) | F68: =IF($C68=0, "", C68) | H68: short FP | I68: 39
C69: =COUNTIFS(Tabelle1[[#All],[Reason]],Statistics!B69, Tabelle1[[#All],[Valid]], "No") -> 0 | E69: =IF($C69=0, "", B69) | F69: =IF($C69=0, "", C69) | H69: und äh | I69: 36
C70: =COUNTIFS(Tabelle1[[#All],[Reason]],Statistics!B70, Tabelle1[[#All],[Valid]], "No") -> 0 | E70: =IF($C70=0, "", B70) | F70: =IF($C70=0, "", C70) | H70: laughter | I70: 30
C71: =COUNTIFS(Tabelle1[[#All],[Reason]],Statistics!B71, Tabelle1[[#All],[Valid]], "No") -> 0 | E71: =IF($C71=0, "", B71) | F71: =IF($C71=0, "", C71) | H71: not enough speech | I71: 27
C72: =COUNTIFS(Tabelle1[[#All],[Reason]],Statistics!B72, Tabelle1[[#All],[Valid]], "No") -> 0 | E72: =IF($C72=0, "", B72) | F72: =IF($C72=0, "", C72) | H72: name | I72: 25
C73: =COUNTIFS(Tabelle1[[#All],[Reason]],Statistics!B73, Tabelle1[[#All],[Valid]], "No") -> 0 | E73: =IF($C73=0, "", B73) | F73: =IF($C73=0, "", C73) | H73: repetition | I73: 21
C74: =COUNTIFS(Tabelle1[[#All],[Reason]],Statistics!B74, Tabelle1[[#All],[Valid]], "No") -> 0 | E74: =IF($C74=0, "", B74) | F74: =IF($C74=0, "", C74) | H74: answer | I74: 12
... C101: =COUNTIFS(Tabelle1[[#All],[Reason]],Statistics!B101, Tabelle1[[#All],[Valid]], "No") -> 0 | E101: =IF($C101=0, "", B101) | F101: =IF($C101=0, "", C101) | H101: active speech | I101: 1
